const jwt = require("jsonwebtoken");
const bcrypt = require("bcrypt");
const User = require("../../database/models/User");
const { mockUsers } = require("../mocks/mockUsers");
const { loadUsers, userLogin } = require("./usersController");

describe("Given a userLogin function", () => {
  describe("When its invoked with a req with a existing username and password", () => {
    test("Then it should call the response status method with 201 and the response json method with a token", async () => {
      jest.spyOn(User, "findOne").mockResolvedValue(true);
      jest.spyOn(bcrypt, "compare").mockResolvedValue(true);
      const expectedToken = "mitoquencito";
      jest.spyOn(jwt, "sign").mockReturnValue(expectedToken);

      const req = {
        body: { username: "manolo", password: "notapasword123" },
      };
      const res = {
        status: jest.fn().mockReturnThis(),
        json: jest.fn(),
      };
      const expectedStatus = 201;

      await userLogin(req, res);

      expect(res.status).toHaveBeenCalledWith(expectedStatus);
      expect(res.json).toHaveBeenCalledWith({ token: expectedToken });
    });
  });

  describe("When its invoked with a req with a wrong username", () => {
    test("Then it should call next", async () => {
      jest.spyOn(User, "findOne").mockResolvedValue(false);

      const req = {
        body: { username: "manolo", password: "notapasword123" },
      };
      const res = {
        status: jest.fn().mockReturnThis(),
        json: jest.fn(),
      };
      const next = jest.fn();

      await userLogin(req, res, next);

      expect(next).toHaveBeenCalled();
    });
  });

  describe("When its invoked with a req with a orrect user but a wrong password", () => {
    test("Then it should call next", async () => {
      jest.spyOn(User, "findOne").mockResolvedValue(true);
      jest.spyOn(bcrypt, "compare").mockResolvedValue(false);
      const expectedToken = "mitoquencito";
      jest.spyOn(jwt, "sign").mockReturnValue(expectedToken);
      const req = {
        body: { username: "manolo", password: "notapasword123" },
      };
      const res = {
        status: jest.fn().mockReturnThis(),
        json: jest.fn(),
      };
      const next = jest.fn();

      await userLogin(req, res, next);

      expect(next).toHaveBeenCalled();
    });
  });
});

describe("given loadUsers function", () => {
  const res = {
    status: jest.fn().mockReturnThis(),
    json: jest.fn(),
  };

  describe("When it's invoked with a response", () => {
    test("Then it should call the response status method with 200 and return the user", async () => {
      User.find = jest.fn().mockResolvedValue(mockUsers);
      const expectedStatus = 200;
      const expectedUsers = {
        users: [
          {
            _id: "6287dcfafc0614bd47bc9c4a",
            name: "Mario",
            username: "marioLG",
            password: "CA32A1E4F9CB46B6D99FC627F9EB4AC606BC3474",
            image: "hfdfhdf.jpg",
            friends: ["6287e11ffc0614bd47bc9c4e"],
            enemies: ["6287e128fc0614bd47bc9c4f"],
          },
          {
            _id: "6287e11ffc0614bd47bc9c4e",
            name: "Maichol",
            username: "queEsEstoMaicol",
            password: "CA32A1E4F9CB46B8D99FC627F9EB4AC606BC3474",
            image: "dsdsdsd.jpg",
            friends: ["6287dcfafc0614bd47bc9c4a"],
            enemies: ["6287e128fc0614bd47bc9c4f"],
          },
        ],
      };

      await loadUsers(null, res);

      expect(res.status).toHaveBeenCalledWith(expectedStatus);
      expect(res.json).toHaveBeenCalledWith(expectedUsers);
    });
  });

  describe("When it's invoke with a response but cant find any user", () => {
    const newError = new Error();
    newError.code = 400;
    newError.errorMessage = "Bad request";

    test("Then it should create a new Error and call next with the new error", async () => {
      User.find = jest.fn().mockResolvedValue(undefined);
      const next = jest.fn().mockReturnThis();

      await loadUsers(null, res, next);

      expect(next).toHaveBeenCalledWith(newError);
    });
  });

  describe("When it's invoked with a response but an error occurs", () => {
    test("Then it should call next", async () => {
      User.find = jest.fn().mockRejectedValue();
      const next = jest.fn().mockReturnThis();

      await loadUsers(null, res, next);

      expect(next).toHaveBeenCalled();
    });
  });
});
